Workbook

Sheet Read me
A1: File C · Budget and bid scenarios (Budget War Room)
A2: Synthetic training data created for this workshop. It is NOT Forbes Advisor data. Brand, lender, insurer, software and competitor names are fictional; competitor domains use the reserved .example suffix.
A4: What is in this file
A5: A live scenario model built on September daily data (1–27 Sep 2026). Baseline metrics are formulas over the "Daily data (Sep)" sheet and use only the rows marked "Yes" in "Include in baseline", so that each baseline reflects current conditions. Your facilitator explains the excluded days after the Lab 3b debrief.
A6: Colour code
A7: Blue text = inputs you can change · Black = formulas · Yellow fill = key assumptions and cells for you to fill in · Green text = values pulled from another sheet.
A8: Your task (Module 3, Budget War Room)
A9: Your team receives an inject card at 14:45, when this file is released. Model it with the tools in this file: "Scenario model" (spend and bid what-ifs: change only the blue inputs on your "Your scenario" row, or ask Copilot to add a row), the smart-cut calculator below it (cutting wasted terms first), "Day-type split" (weekdays against weekends) and "October pacing". Then prepare a 60-second decision: the number, the risk, the ask.
A10: Diminishing returns: buying more clicks costs more per click. The model raises CPC by the "CPC uplift per +10% spend" assumption for any spend above today's level.
A11: Metric definitions
A12: Click-outs = clicks from the comparison page to a partner offer (the conversion we optimise). Revenue = partner commission earned (USD).
A13: CTR = Clicks / Impressions · CPC = Cost / Clicks · Click-out rate = Click-outs / Clicks · RPC (revenue per click) = Revenue / Clicks
... A20: 4. Check before you trust: ask Copilot to show the formula it used, recompute one number yourself, and confirm totals match the source table.

Sheet Daily data (Sep)
A1: Date | B1: Day | C1: Weekend | D1: Vertical | E1: Impressions | F1: Clicks | G1: Cost (USD) | H1: Click-outs | I1: Revenue (USD) | J1: Search lost IS (budget) | K1: Include in baseline | L1: Why excluded
A2: 46266 | B2: Tue | C2: No | D2: Business Software (CRM) | E2: 6144 | F2: 247 | G2: 2994.48 | H2: 51 | I2: 3322.48 | J2: 0.0013 | K2: Yes
A3: 46267 | B3: Wed | C3: No | D3: Business Software (CRM) | E3: 6266 | F3: 217 | G3: 2608.69 | H3: 45 | I3: 2907.44 | J3: 0.0035 | K3: Yes
A4: 46268 | B4: Thu | C4: No | D4: Business Software (CRM) | E4: 6223 | F4: 247 | G4: 3191.3 | H4: 42 | I4: 2981.43 | J4: 0.0006 | K4: Yes
A5: 46269 | B5: Fri | C5: No | D5: Business Software (CRM) | E5: 6251 | F5: 241 | G5: 2845.48 | H5: 46 | I5: 3132.83 | J5: 0.0026 | K5: Yes
A6: 46270 | B6: Sat | C6: Yes | D6: Business Software (CRM) | E6: 2744 | F6: 90 | G6: 965.02 | H6: 6 | I6: 406.5 | J6: 0.0058 | K6: Yes
A7: 46271 | B7: Sun | C7: Yes | D7: Business Software (CRM) | E7: 2719 | F7: 115 | G7: 1260.43 | H7: 9 | I7: 590.25 | J7: 0.004 | K7: Yes
A8: 46272 | B8: Mon | C8: No | D8: Business Software (CRM) | E8: 2938 | F8: 94 | G8: 1053.46 | H8: 9 | I8: 559.51 | J8: 0.0062 | K8: Yes
A9: 46273 | B9: Tue | C9: No | D9: Business Software (CRM) | E9: 5904 | F9: 217 | G9: 2652.43 | H9: 27 | I9: 1832.61 | J9: 0.0099 | K9: Yes
A10: 46274 | B10: Wed | C10: No | D10: Business Software (CRM) | E10: 6060 | F10: 215 | G10: 2803.29 | H10: 29 | I10: 1974.19 | J10: 0.0041 | K10: Yes
A11: 46275 | B11: Thu | C11: No | D11: Business Software (CRM) | E11: 6454 | F11: 232 | G11: 2700.04 | H11: 44 | I11: 2909.74 | J11: 0.0016 | K11: Yes
A12: 46276 | B12: Fri | C12: No | D12: Business Software (CRM) | E12: 5957 | F12: 244 | G12: 3009.55 | H12: 54 | I12: 4028.56 | J12: 0.0044 | K12: Yes
A13: 46277 | B13: Sat | C13: Yes | D13: Business Software (CRM) | E13: 2648 | F13: 100 | G13: 1043.09 | H13: 9 | I13: 610.71 | J13: 0.0032 | K13: Yes
... A28: 46292 | B28: Sun | C28: Yes | D28: Business Software (CRM) | E28: 2875 | F28: 107 | G28: 1122.42 | H28: 10 | I28: 713.2 | J28: 0.0002 | K28: Yes
A29: 46266 | B29: Tue | C29: No | D29: Credit Cards | E29: 18096 | F29: 787 | G29: 3463.71 | H29: 224 | I29: 5109.47 | J29: 0.0023 | K29: No | L29: Before the baseline window
A30: 46267 | B30: Wed | C30: No | D30: Credit Cards | E30: 18073 | F30: 735 | G30: 3514 | H30: 207 | I30: 4598.94 | J30: 0.0072 | K30: No | L30: Before the baseline window
A31: 46268 | B31: Thu | C31: No | D31: Credit Cards | E31: 20030 | F31: 894 | G31: 4064.6 | H31: 262 | I31: 6018.45 | J31: 0.0066 | K31: No | L31: Before the baseline window
A32: 46269 | B32: Fri | C32: No | D32: Credit Cards | E32: 18134 | F32: 814 | G32: 3751.81 | H32: 228 | I32: 5510.77 | J32: 0.0094 | K32: No | L32: Before the baseline window
A33: 46270 | B33: Sat | C33: Yes | D33: Credit Cards | E33: 16304 | F33: 726 | G33: 3434.7 | H33: 231 | I33: 5138.25 | J33: 0.0038 | K33: No | L33: Before the baseline window
A34: 46271 | B34: Sun | C34: Yes | D34: Credit Cards | E34: 16319 | F34: 691 | G34: 3082.19 | H34: 165 | I34: 3536.16 | J34: 0.0011 | K34: No | L34: Before the baseline window
A35: 46272 | B35: Mon | C35: No | D35: Credit Cards | E35: 17591 | F35: 763 | G35: 3456.74 | H35: 210 | I35: 4660.39 | J35: 0.0049 | K35: No | L35: Before the baseline window
A36: 46273 | B36: Tue | C36: No | D36: Credit Cards | E36: 15218 | F36: 654 | G36: 4480.6 | H36: 204 | I36: 4821.5 | J36: 0.0034 | K36: Yes
A37: 46274 | B37: Wed | C37: No | D37: Credit Cards | E37: 15461 | F37: 717 | G37: 4449.46 | H37: 191 | I37: 4458.66 | J37: 0.0067 | K37: Yes
A38: 46275 | B38: Thu | C38: No | D38: Credit Cards | E38: 15490 | F38: 684 | G38: 4258.57 | H38: 187 | I38: 4309.93 | J38: 0.0024 | K38: Yes
A39: 46276 | B39: Fri | C39: No | D39: Credit Cards | E39: 14899 | F39: 666 | G39: 4203.18 | H39: 202 | I39: 4961.01 | J39: 0.0048 | K39: Yes
A40: 46277 | B40: Sat | C40: Yes | D40: Credit Cards | E40: 15016 | F40: 681 | G40: 3958.65 | H40: 202 | I40: 4672.44 | J40: 0.004 | K40: Yes
A41: 46278 | B41: Sun | C41: Yes | D41: Credit Cards | E41: 12886 | F41: 575 | G41: 3641.73 | H41: 170 | I41: 3746.51 | J41: 0.0051 | K41: Yes
A42: 46279 | B42: Mon | C42: No | D42: Credit Cards | E42: 15824 | F42: 727 | G42: 4272.32 | H42: 199 | I42: 4344.25 | J42: 0.0006 | K42: Yes
A43: 46280 | B43: Tue | C43: No | D43: Credit Cards | E43: 16943 | F43: 696 | G43: 4111.69 | H43: 196 | I43: 4668.81 | J43: 0.0016 | K43: Yes
A44: 46281 | B44: Wed | C44: No | D44: Credit Cards | E44: 15308 | F44: 695 | G44: 4329.09 | H44: 231 | I44: 5096.61 | J44: 0.0006 | K44: Yes
A45: 46282 | B45: Thu | C45: No | D45: Credit Cards | E45: 15675 | F45: 664 | G45: 3992.43 | H45: 194 | I45: 4447.45 | J45: 0.0037 | K45: Yes
A46: 46283 | B46: Fri | C46: No | D46: Credit Cards | E46: 14344 | F46: 612 | G46: 3663.76 | H46: 172 | I46: 3923.74 | J46: 0.0011 | K46: Yes
A47: 46284 | B47: Sat | C47: Yes | D47: Credit Cards | E47: 14152 | F47: 572 | G47: 3524.34 | H47: 186 | I47: 4277.09 | J47: 0.0041 | K47: Yes
... A55: 46292 | B55: Sun | C55: Yes | D55: Credit Cards | E55: 14558 | F55: 588 | G55: 3668.27 | H55: 172 | I55: 3771.48 | J55: 0.002 | K55: Yes
A56: 46266 | B56: Tue | C56: No | D56: Personal Loans | E56: 18892 | F56: 1136 | G56: 8763.35 | H56: 253 | I56: 11066.48 | J56: 0.0049 | K56: No | L56: Before the baseline window
A57: 46267 | B57: Wed | C57: No | D57: Personal Loans | E57: 21180 | F57: 1238 | G57: 10695.22 | H57: 289 | I57: 12737.45 | J57: 0.0049 | K57: No | L57: Before the baseline window
A58: 46268 | B58: Thu | C58: No | D58: Personal Loans | E58: 20966 | F58: 1219 | G58: 9941.05 | H58: 263 | I58: 11334.8 | J58: 0.0067 | K58: No | L58: Before the baseline window
A59: 46269 | B59: Fri | C59: No | D59: Personal Loans | E59: 21463 | F59: 1242 | G59: 9640.22 | H59: 256 | I59: 11925.01 | J59: 0.0058 | K59: No | L59: Before the baseline window
A60: 46270 | B60: Sat | C60: Yes | D60: Personal Loans | E60: 16451 | F60: 976 | G60: 7707.93 | H60: 224 | I60: 9597.25 | J60: 0.004 | K60: No | L60: Before the baseline window
A61: 46271 | B61: Sun | C61: Yes | D61: Personal Loans | E61: 15384 | F61: 973 | G61: 7914.71 | H61: 203 | I61: 9471.61 | J61: 0.0009 | K61: No | L61: Before the baseline window
...

Sheet Baseline
A1: Baseline: daily averages for current conditions (September)
A2: Baseline windows: Loans 9–27 Sep, excluding 14–15 Sep · Cards 8–27 Sep · Pet and CRM 1–27 Sep. The Lab 3b debrief explains why.
A3: Vertical | B3: Days in baseline | C3: Cost / day (USD) | D3: Clicks / day | E3: Avg CPC (USD) | F3: Click-out rate | G3: Revenue per click-out (USD) | H3: RPC (USD) | I3: Revenue / day (USD) | J3: ROAS | K3: Avg lost IS (budget) | L3: Daily budget (USD) | M3: Target ROAS
A4: Personal Loans | B4: =COUNTIFS('Daily data (Sep)'!$D$2:$D$109,$A4,'Daily data (Sep)'!$K$2:$K$109,"Yes") -> 17 | C4: =SUMIFS('Daily data (Sep)'!$G$2:$G$109,'Daily data (Sep)'!$D$2:$D$109,$A4,'Daily data (Sep)'!$K$2:$K$109,"Yes")/B4 -> 9939.3676 | D4: =SUMIFS('Daily data (Sep)'!$F$2:$F$109,'Daily data (Sep)'!$D$2:$D$109,$A4,'Daily data (Sep)'!$K$2:$K$109,"Yes")/B4 -> 1281.8824 | E4: =C4/D4 -> 7.7537284 | F4: =SUMIFS('Daily data (Sep)'!$H$2:$H$109,'Daily data (Sep)'!$D$2:$D$109,$A4,'Daily data (Sep)'!$K$2:$K$109,"Yes")/SUMIFS('Daily data (Sep)'!$F$2:$F$109,'Daily data (Sep)'!$D$2:$D$109,$A4,'Daily data (Sep)'!$K$2:$K$109,"Yes") -> 0.19103341 | G4: =SUMIFS('Daily data (Sep)'!$I$2:$I$109,'Daily data (Sep)'!$D$2:$D$109,$A4,'Daily data (Sep)'!$K$2:$K$109,"Yes")/SUMIFS('Daily data (Sep)'!$H$2:$H$109,'Daily data (Sep)'!$D$2:$D$109,$A4,'Daily data (Sep)'!$K$2:$K$109,"Yes") -> 42.682971 | H4: =F4*G4 -> 8.1538734 | I4: =D4*H4 -> 10452.306 | J4: =I4/C4 -> 1.0516068 | K4: =AVERAGEIFS('Daily data (Sep)'!$J$2:$J$109,'Daily data (Sep)'!$D$2:$D$109,$A4,'Daily data (Sep)'!$K$2:$K$109,"Yes") -> 0.0028117647 | L4: 14000 | M4: 1.2
A5: Credit Cards | B5: =COUNTIFS('Daily data (Sep)'!$D$2:$D$109,$A5,'Daily data (Sep)'!$K$2:$K$109,"Yes") -> 20 | C5: =SUMIFS('Daily data (Sep)'!$G$2:$G$109,'Daily data (Sep)'!$D$2:$D$109,$A5,'Daily data (Sep)'!$K$2:$K$109,"Yes")/B5 -> 4001.7205 | D5: =SUMIFS('Daily data (Sep)'!$F$2:$F$109,'Daily data (Sep)'!$D$2:$D$109,$A5,'Daily data (Sep)'!$K$2:$K$109,"Yes")/B5 -> 654.45 | E5: =C5/D5 -> 6.1146314 | F5: =SUMIFS('Daily data (Sep)'!$H$2:$H$109,'Daily data (Sep)'!$D$2:$D$109,$A5,'Daily data (Sep)'!$K$2:$K$109,"Yes")/SUMIFS('Daily data (Sep)'!$F$2:$F$109,'Daily data (Sep)'!$D$2:$D$109,$A5,'Daily data (Sep)'!$K$2:$K$109,"Yes") -> 0.29368172 | G5: =SUMIFS('Daily data (Sep)'!$I$2:$I$109,'Daily data (Sep)'!$D$2:$D$109,$A5,'Daily data (Sep)'!$K$2:$K$109,"Yes")/SUMIFS('Daily data (Sep)'!$H$2:$H$109,'Daily data (Sep)'!$D$2:$D$109,$A5,'Daily data (Sep)'!$K$2:$K$109,"Yes") -> 22.709735 | H5: =F5*G5 -> 6.6694339 | I5: =D5*H5 -> 4364.811 | J5: =I5/C5 -> 1.0907336 | K5: =AVERAGEIFS('Daily data (Sep)'!$J$2:$J$109,'Daily data (Sep)'!$D$2:$D$109,$A5,'Daily data (Sep)'!$K$2:$K$109,"Yes") -> 0.00271 | L5: 6000 | M5: 1.25
A6: Pet Insurance | B6: =COUNTIFS('Daily data (Sep)'!$D$2:$D$109,$A6,'Daily data (Sep)'!$K$2:$K$109,"Yes") -> 27 | C6: =SUMIFS('Daily data (Sep)'!$G$2:$G$109,'Daily data (Sep)'!$D$2:$D$109,$A6,'Daily data (Sep)'!$K$2:$K$109,"Yes")/B6 -> 2265.847 | D6: =SUMIFS('Daily data (Sep)'!$F$2:$F$109,'Daily data (Sep)'!$D$2:$D$109,$A6,'Daily data (Sep)'!$K$2:$K$109,"Yes")/B6 -> 707.62963 | E6: =C6/D6 -> 3.202024 | F6: =SUMIFS('Daily data (Sep)'!$H$2:$H$109,'Daily data (Sep)'!$D$2:$D$109,$A6,'Daily data (Sep)'!$K$2:$K$109,"Yes")/SUMIFS('Daily data (Sep)'!$F$2:$F$109,'Daily data (Sep)'!$D$2:$D$109,$A6,'Daily data (Sep)'!$K$2:$K$109,"Yes") -> 0.25259081 | G6: =SUMIFS('Daily data (Sep)'!$I$2:$I$109,'Daily data (Sep)'!$D$2:$D$109,$A6,'Daily data (Sep)'!$K$2:$K$109,"Yes")/SUMIFS('Daily data (Sep)'!$H$2:$H$109,'Daily data (Sep)'!$D$2:$D$109,$A6,'Daily data (Sep)'!$K$2:$K$109,"Yes") -> 20.951842 | H6: =F6*G6 -> 5.2922428 | I6: =D6*H6 -> 3744.9478 | J6: =I6/C6 -> 1.6527805 | K6: =AVERAGEIFS('Daily data (Sep)'!$J$2:$J$109,'Daily data (Sep)'!$D$2:$D$109,$A6,'Daily data (Sep)'!$K$2:$K$109,"Yes") -> 0.40622963 | L6: 2300 | M6: 1.3
A7: Business Software (CRM) | B7: =COUNTIFS('Daily data (Sep)'!$D$2:$D$109,$A7,'Daily data (Sep)'!$K$2:$K$109,"Yes") -> 27 | C7: =SUMIFS('Daily data (Sep)'!$G$2:$G$109,'Daily data (Sep)'!$D$2:$D$109,$A7,'Daily data (Sep)'!$K$2:$K$109,"Yes")/B7 -> 2378.7744 | D7: =SUMIFS('Daily data (Sep)'!$F$2:$F$109,'Daily data (Sep)'!$D$2:$D$109,$A7,'Daily data (Sep)'!$K$2:$K$109,"Yes")/B7 -> 198.25926 | E7: =C7/D7 -> 11.998302 | F7: =SUMIFS('Daily data (Sep)'!$H$2:$H$109,'Daily data (Sep)'!$D$2:$D$109,$A7,'Daily data (Sep)'!$K$2:$K$109,"Yes")/SUMIFS('Daily data (Sep)'!$F$2:$F$109,'Daily data (Sep)'!$D$2:$D$109,$A7,'Daily data (Sep)'!$K$2:$K$109,"Yes") -> 0.17018494 | G7: =SUMIFS('Daily data (Sep)'!$I$2:$I$109,'Daily data (Sep)'!$D$2:$D$109,$A7,'Daily data (Sep)'!$K$2:$K$109,"Yes")/SUMIFS('Daily data (Sep)'!$H$2:$H$109,'Daily data (Sep)'!$D$2:$D$109,$A7,'Daily data (Sep)'!$K$2:$K$109,"Yes") -> 67.810439 | H7: =F7*G7 -> 11.540316 | I7: =D7*H7 -> 2287.9744 | J7: =I7/C7 -> 0.96182908 | K7: =AVERAGEIFS('Daily data (Sep)'!$J$2:$J$109,'Daily data (Sep)'!$D$2:$D$109,$A7,'Daily data (Sep)'!$K$2:$K$109,"Yes") -> 0.0035148148 | L7: 4000 | M7: 1.25
A9: Daily budget and target ROAS are inputs (blue). Target ROAS values are workshop assumptions agreed for this exercise.

Sheet Scenario model
A1: Scenario model: change the blue inputs; everything else recalculates
A2: Global assumptions
A3: CPC uplift per +10% spend above today (diminishing returns) | B3: 0.015 | C3: Workshop assumption: each +10% of extra daily spend raises average CPC by 1.5% (the extra impressions you buy cost a little more). Challenge it.
A4: Click volume change per 1% CPC cut (bid-down elasticity) | B4: 1.2 | C4: Workshop assumption: bidding CPC down by 1% loses about 1.2% of clicks (used only when "CPC change" is negative). Challenge it.
A6: Vertical | B6: Scenario | C6: Spend cap change (vs today's spend) | D6: CPC change (bids or market) | E6: Click-out rate change | F6: Revenue per click-out change | G6: Baseline cost / day | H6: Baseline CPC | I6: Lost IS (budget) | J6: Potential spend / day | K6: New spend cap / day | L6: New spend / day | M6: New CPC | N6: New clicks / day | O6: New click-outs / day | P6: New revenue / day | Q6: New ROAS | R6: New profit / day | S6: Profit change / day | T6: Meets target ROAS? | U6: Marginal ROAS (extra revenue ÷ extra spend)
A7: Personal Loans | B7: Baseline (no change) | C7: 0 | D7: 0 | E7: 0 | F7: 0 | G7: =Baseline!$C$4 -> 9939.3676 | H7: =Baseline!$E$4 -> 7.7537284 | I7: =Baseline!$K$4 -> 0.0028117647 | J7: =G7/(1-I7)*(1+D7) -> 9967.3936 | K7: =G7*(1+C7) -> 9939.3676 | L7: =N7*M7 -> 9939.3676 | M7: =H7*(1+D7)*(1+IF(D7<0,0,$B$3*MAX(0,MIN(K7,J7)/(G7*(1+D7))-1)/0.1)) -> 7.7537284 | N7: =IF(D7<0,MIN(Baseline!$D$4*(1+$B$4*D7),K7/M7),MIN(K7,J7)/M7) -> 1281.8824 | O7: =N7*Baseline!$F$4*(1+E7) -> 244.88235 | P7: =O7*Baseline!$G$4*(1+F7) -> 10452.306 | Q7: =P7/L7 -> 1.0516068 | R7: =P7-L7 -> 512.93882 | S7: =R7-(Baseline!$I$4-Baseline!$C$4) -> 0 | T7: =IF(ROUND(Q7,2)>=Baseline!$M$4,"Yes","No") -> No
A8: Personal Loans | B8: Your scenario | C8: 0 | D8: 0 | E8: 0 | F8: 0 | G8: =Baseline!$C$4 -> 9939.3676 | H8: =Baseline!$E$4 -> 7.7537284 | I8: =Baseline!$K$4 -> 0.0028117647 | J8: =G8/(1-I8)*(1+D8) -> 9967.3936 | K8: =G8*(1+C8) -> 9939.3676 | L8: =N8*M8 -> 9939.3676 | M8: =H8*(1+D8)*(1+IF(D8<0,0,$B$3*MAX(0,MIN(K8,J8)/(G8*(1+D8))-1)/0.1)) -> 7.7537284 | N8: =IF(D8<0,MIN(Baseline!$D$4*(1+$B$4*D8),K8/M8),MIN(K8,J8)/M8) -> 1281.8824 | O8: =N8*Baseline!$F$4*(1+E8) -> 244.88235 | P8: =O8*Baseline!$G$4*(1+F8) -> 10452.306 | Q8: =P8/L8 -> 1.0516068 | R8: =P8-L8 -> 512.93882 | S8: =R8-(Baseline!$I$4-Baseline!$C$4) -> 0 | T8: =IF(ROUND(Q8,2)>=Baseline!$M$4,"Yes","No") -> No | U8: =IF(ABS(L8-L7)<0.5,"",(P8-P7)/(L8-L7))
A9: Credit Cards | B9: Baseline (no change) | C9: 0 | D9: 0 | E9: 0 | F9: 0 | G9: =Baseline!$C$5 -> 4001.7205 | H9: =Baseline!$E$5 -> 6.1146314 | I9: =Baseline!$K$5 -> 0.00271 | J9: =G9/(1-I9)*(1+D9) -> 4012.5946 | K9: =G9*(1+C9) -> 4001.7205 | L9: =N9*M9 -> 4001.7205 | M9: =H9*(1+D9)*(1+IF(D9<0,0,$B$3*MAX(0,MIN(K9,J9)/(G9*(1+D9))-1)/0.1)) -> 6.1146314 | N9: =IF(D9<0,MIN(Baseline!$D$5*(1+$B$4*D9),K9/M9),MIN(K9,J9)/M9) -> 654.45 | O9: =N9*Baseline!$F$5*(1+E9) -> 192.2 | P9: =O9*Baseline!$G$5*(1+F9) -> 4364.811 | Q9: =P9/L9 -> 1.0907336 | R9: =P9-L9 -> 363.0905 | S9: =R9-(Baseline!$I$5-Baseline!$C$5) -> 0 | T9: =IF(ROUND(Q9,2)>=Baseline!$M$5,"Yes","No") -> No
A10: Credit Cards | B10: Your scenario | C10: 0 | D10: 0 | E10: 0 | F10: 0 | G10: =Baseline!$C$5 -> 4001.7205 | H10: =Baseline!$E$5 -> 6.1146314 | I10: =Baseline!$K$5 -> 0.00271 | J10: =G10/(1-I10)*(1+D10) -> 4012.5946 | K10: =G10*(1+C10) -> 4001.7205 | L10: =N10*M10 -> 4001.7205 | M10: =H10*(1+D10)*(1+IF(D10<0,0,$B$3*MAX(0,MIN(K10,J10)/(G10*(1+D10))-1)/0.1)) -> 6.1146314 | N10: =IF(D10<0,MIN(Baseline!$D$5*(1+$B$4*D10),K10/M10),MIN(K10,J10)/M10) -> 654.45 | O10: =N10*Baseline!$F$5*(1+E10) -> 192.2 | P10: =O10*Baseline!$G$5*(1+F10) -> 4364.811 | Q10: =P10/L10 -> 1.0907336 | R10: =P10-L10 -> 363.0905 | S10: =R10-(Baseline!$I$5-Baseline!$C$5) -> 0 | T10: =IF(ROUND(Q10,2)>=Baseline!$M$5,"Yes","No") -> No | U10: =IF(ABS(L10-L9)<0.5,"",(P10-P9)/(L10-L9))
A11: Pet Insurance | B11: Baseline (no change) | C11: 0 | D11: 0 | E11: 0 | F11: 0 | G11: =Baseline!$C$6 -> 2265.847 | H11: =Baseline!$E$6 -> 3.202024 | I11: =Baseline!$K$6 -> 0.40622963 | J11: =G11/(1-I11)*(1+D11) -> 3816.0325 | K11: =G11*(1+C11) -> 2265.847 | L11: =N11*M11 -> 2265.847 | M11: =H11*(1+D11)*(1+IF(D11<0,0,$B$3*MAX(0,MIN(K11,J11)/(G11*(1+D11))-1)/0.1)) -> 3.202024 | N11: =IF(D11<0,MIN(Baseline!$D$6*(1+$B$4*D11),K11/M11),MIN(K11,J11)/M11) -> 707.62963 | O11: =N11*Baseline!$F$6*(1+E11) -> 178.74074 | P11: =O11*Baseline!$G$6*(1+F11) -> 3744.9478 | Q11: =P11/L11 -> 1.6527805 | R11: =P11-L11 -> 1479.1007 | S11: =R11-(Baseline!$I$6-Baseline!$C$6) -> 0 | T11: =IF(ROUND(Q11,2)>=Baseline!$M$6,"Yes","No") -> Yes
A12: Pet Insurance | B12: Your scenario | C12: 0 | D12: 0 | E12: 0 | F12: 0 | G12: =Baseline!$C$6 -> 2265.847 | H12: =Baseline!$E$6 -> 3.202024 | I12: =Baseline!$K$6 -> 0.40622963 | J12: =G12/(1-I12)*(1+D12) -> 3816.0325 | K12: =G12*(1+C12) -> 2265.847 | L12: =N12*M12 -> 2265.847 | M12: =H12*(1+D12)*(1+IF(D12<0,0,$B$3*MAX(0,MIN(K12,J12)/(G12*(1+D12))-1)/0.1)) -> 3.202024 | N12: =IF(D12<0,MIN(Baseline!$D$6*(1+$B$4*D12),K12/M12),MIN(K12,J12)/M12) -> 707.62963 | O12: =N12*Baseline!$F$6*(1+E12) -> 178.74074 | P12: =O12*Baseline!$G$6*(1+F12) -> 3744.9478 | Q12: =P12/L12 -> 1.6527805 | R12: =P12-L12 -> 1479.1007 | S12: =R12-(Baseline!$I$6-Baseline!$C$6) -> 0 | T12: =IF(ROUND(Q12,2)>=Baseline!$M$6,"Yes","No") -> Yes | U12: =IF(ABS(L12-L11)<0.5,"",(P12-P11)/(L12-L11))
A13: Business Software (CRM) | B13: Baseline (no change) | C13: 0 | D13: 0 | E13: 0 | F13: 0 | G13: =Baseline!$C$7 -> 2378.7744 | H13: =Baseline!$E$7 -> 11.998302 | I13: =Baseline!$K$7 -> 0.0035148148 | J13: =G13/(1-I13)*(1+D13) -> 2387.1649 | K13: =G13*(1+C13) -> 2378.7744 | L13: =N13*M13 -> 2378.7744 | M13: =H13*(1+D13)*(1+IF(D13<0,0,$B$3*MAX(0,MIN(K13,J13)/(G13*(1+D13))-1)/0.1)) -> 11.998302 | N13: =IF(D13<0,MIN(Baseline!$D$7*(1+$B$4*D13),K13/M13),MIN(K13,J13)/M13) -> 198.25926 | O13: =N13*Baseline!$F$7*(1+E13) -> 33.740741 | P13: =O13*Baseline!$G$7*(1+F13) -> 2287.9744 | Q13: =P13/L13 -> 0.96182908 | R13: =P13-L13 -> -90.8 | S13: =R13-(Baseline!$I$7-Baseline!$C$7) -> 0 | T13: =IF(ROUND(Q13,2)>=Baseline!$M$7,"Yes","No") -> No
A14: Business Software (CRM) | B14: Your scenario | C14: 0 | D14: 0 | E14: 0 | F14: 0 | G14: =Baseline!$C$7 -> 2378.7744 | H14: =Baseline!$E$7 -> 11.998302 | I14: =Baseline!$K$7 -> 0.0035148148 | J14: =G14/(1-I14)*(1+D14) -> 2387.1649 | K14: =G14*(1+C14) -> 2378.7744 | L14: =N14*M14 -> 2378.7744 | M14: =H14*(1+D14)*(1+IF(D14<0,0,$B$3*MAX(0,MIN(K14,J14)/(G14*(1+D14))-1)/0.1)) -> 11.998302 | N14: =IF(D14<0,MIN(Baseline!$D$7*(1+$B$4*D14),K14/M14),MIN(K14,J14)/M14) -> 198.25926 | O14: =N14*Baseline!$F$7*(1+E14) -> 33.740741 | P14: =O14*Baseline!$G$7*(1+F14) -> 2287.9744 | Q14: =P14/L14 -> 0.96182908 | R14: =P14-L14 -> -90.8 | S14: =R14-(Baseline!$I$7-Baseline!$C$7) -> 0 | T14: =IF(ROUND(Q14,2)>=Baseline!$M$7,"Yes","No") -> No | U14: =IF(ABS(L14-L13)<0.5,"",(P14-P13)/(L14-L13))
A16: How to read it
A17: • "Spend cap change" applies to today's average spend (Baseline cost / day), not to the Google daily budget: +30% for Pet means about 30% more than the September average.
A18: • New spend = the lower of the new spend cap and the demand you could buy (today's spend grossed up for impressions lost to budget).
A19: • Spend cuts are modelled as proportional cuts across all terms. Compare with cutting wasted terms first (smart-cut calculator below).
A20: • When "CPC change" is negative (bidding down), clicks fall by the elasticity assumption and no CPC uplift applies.
A21: • Max CPC at target ROAS = revenue per click ÷ target ROAS. Above it, every extra click loses money against the target.
A22: • Marginal ROAS (last column) = extra revenue ÷ extra spend against the baseline row. A campaign can stay above target on average while the extra spend earns less than it costs.
A24: Smart-cut calculator (Team Loans): cut wasted terms first, then the rest proportionally
A25: Wasted spend you found in Lab 3a, 1–27 Sep (USD)
A26: Revenue earned by those wasted terms, 1–27 Sep (USD)
A27: Days covered by the search terms report | B27: 27
A28: Spend cut required, as a share of today's daily spend (a 20% cut = 20%; the sign does not matter)
A29: Spend cut per day (USD) | B29: =ABS(N(B28))*G7 -> 0
A30: Cut from wasted terms per day | B30: =MIN(B29,N(B25)/B27) -> 0
A31: Revenue lost from wasted terms per day | B31: =IF(N(B25)>0,N(B26)*B30/B25,0) -> 0
A32: Remaining cut, taken proportionally (per day) | B32: =B29-B30 -> 0
A33: Revenue lost on the remaining cut (per day) | B33: =B32*Baseline!$J$4 -> 0
A34: Total revenue lost per day: smart cut | B34: =B31+B33 -> 0
A35: Total revenue lost per day: proportional cut | B35: =B29*Baseline!$J$4 -> 0
A36: Revenue kept per day by cutting smart | B36: =B35-B34 -> 0
A37: Type your Lab 3a numbers and the cut on your inject card into the yellow cells. The calculator shows 0 until you do.

Sheet Day-type split
A1: Weekdays against weekends, September (any vertical)
A2: Vertical | D2: Pick a vertical in the yellow cell. The table stays blank until you do. It uses the baseline days only ("Include in baseline" = Yes on the daily sheet).
A4: Day type | B4: Days | C4: Cost / day (USD) | D4: Clicks / day | E4: Click-out rate | F4: Revenue / day (USD) | G4: ROAS | H4: Profit / day (USD) | I4: Days per week | J4: Profit per week (USD)
A5: Weekdays | B5: =IF($B$2="","",COUNTIFS('Daily data (Sep)'!$D$2:$D$109,$B$2,'Daily data (Sep)'!$C$2:$C$109,"No",'Daily data (Sep)'!$K$2:$K$109,"Yes")) | C5: =IF($B$2="","",SUMIFS('Daily data (Sep)'!$G$2:$G$109,'Daily data (Sep)'!$D$2:$D$109,$B$2,'Daily data (Sep)'!$C$2:$C$109,"No",'Daily data (Sep)'!$K$2:$K$109,"Yes")/B5) | D5: =IF($B$2="","",SUMIFS('Daily data (Sep)'!$F$2:$F$109,'Daily data (Sep)'!$D$2:$D$109,$B$2,'Daily data (Sep)'!$C$2:$C$109,"No",'Daily data (Sep)'!$K$2:$K$109,"Yes")/B5) | E5: =IF($B$2="","",SUMIFS('Daily data (Sep)'!$H$2:$H$109,'Daily data (Sep)'!$D$2:$D$109,$B$2,'Daily data (Sep)'!$C$2:$C$109,"No",'Daily data (Sep)'!$K$2:$K$109,"Yes")/SUMIFS('Daily data (Sep)'!$F$2:$F$109,'Daily data (Sep)'!$D$2:$D$109,$B$2,'Daily data (Sep)'!$C$2:$C$109,"No",'Daily data (Sep)'!$K$2:$K$109,"Yes")) | F5: =IF($B$2="","",SUMIFS('Daily data (Sep)'!$I$2:$I$109,'Daily data (Sep)'!$D$2:$D$109,$B$2,'Daily data (Sep)'!$C$2:$C$109,"No",'Daily data (Sep)'!$K$2:$K$109,"Yes")/B5) | G5: =IF($B$2="","",F5/C5) | H5: =IF($B$2="","",F5-C5) | I5: 5 | J5: =IF($B$2="","",H5*I5)
A6: Weekends | B6: =IF($B$2="","",COUNTIFS('Daily data (Sep)'!$D$2:$D$109,$B$2,'Daily data (Sep)'!$C$2:$C$109,"Yes",'Daily data (Sep)'!$K$2:$K$109,"Yes")) | C6: =IF($B$2="","",SUMIFS('Daily data (Sep)'!$G$2:$G$109,'Daily data (Sep)'!$D$2:$D$109,$B$2,'Daily data (Sep)'!$C$2:$C$109,"Yes",'Daily data (Sep)'!$K$2:$K$109,"Yes")/B6) | D6: =IF($B$2="","",SUMIFS('Daily data (Sep)'!$F$2:$F$109,'Daily data (Sep)'!$D$2:$D$109,$B$2,'Daily data (Sep)'!$C$2:$C$109,"Yes",'Daily data (Sep)'!$K$2:$K$109,"Yes")/B6) | E6: =IF($B$2="","",SUMIFS('Daily data (Sep)'!$H$2:$H$109,'Daily data (Sep)'!$D$2:$D$109,$B$2,'Daily data (Sep)'!$C$2:$C$109,"Yes",'Daily data (Sep)'!$K$2:$K$109,"Yes")/SUMIFS('Daily data (Sep)'!$F$2:$F$109,'Daily data (Sep)'!$D$2:$D$109,$B$2,'Daily data (Sep)'!$C$2:$C$109,"Yes",'Daily data (Sep)'!$K$2:$K$109,"Yes")) | F6: =IF($B$2="","",SUMIFS('Daily data (Sep)'!$I$2:$I$109,'Daily data (Sep)'!$D$2:$D$109,$B$2,'Daily data (Sep)'!$C$2:$C$109,"Yes",'Daily data (Sep)'!$K$2:$K$109,"Yes")/B6) | G6: =IF($B$2="","",F6/C6) | H6: =IF($B$2="","",F6-C6) | I6: 2 | J6: =IF($B$2="","",H6*I6)
A8: Target ROAS for this vertical | B8: =IF($B$2="","",INDEX(Baseline!$M$4:$M$7,MATCH($B$2,Baseline!$A$4:$A$7,0)))
A9: Highest weekday CPC that meets the target | B9: =IF($B$2="","",F5/D5/B8)
A10: Current weekday CPC | B10: =IF($B$2="","",C5/D5)
A11: Weekday CPC change needed | B11: =IF($B$2="","",B9/B10-1)
A13: ROAS = revenue ÷ cost. Highest CPC that meets the target = revenue per click ÷ target ROAS. Check one number by hand before you use it.

Sheet October pacing
A1: October 2026 pacing check (as of Sun 4 Oct)
A2: Month-to-date spend (1–4 Oct) and monthly budgets are inputs. 1–4 Oct = Thu, Fri, Sat, Sun. October has 22 weekdays and 9 weekend days.
A4: Vertical | B4: Monthly budget (USD) | C4: MTD spend (USD) | D4: Days elapsed | E4: Days in month | F4: Linear projection (USD) | G4: Pace vs budget | H4: Required spend / day for rest of month (USD) | I4: Weekday share of weekly spend | J4: Remaining weekdays | K4: Remaining weekend days | L4: Day-weighted projection (USD) | M4: Day-weighted pace
A5: Personal Loans | B5: 308000 | C5: 40680 | D5: 4 | E5: 31 | F5: =C5/D5*E5 -> 315270 | G5: =F5/B5-1 -> 0.023603896 | H5: =(B5-C5)/(E5-D5) -> 9900.7407 | I5: =5*SUMIFS('Daily data (Sep)'!$G$2:$G$109,'Daily data (Sep)'!$D$2:$D$109,$A5,'Daily data (Sep)'!$C$2:$C$109,"No",'Daily data (Sep)'!$K$2:$K$109,"Yes")/COUNTIFS('Daily data (Sep)'!$D$2:$D$109,$A5,'Daily data (Sep)'!$C$2:$C$109,"No",'Daily data (Sep)'!$K$2:$K$109,"Yes")/(5*SUMIFS('Daily data (Sep)'!$G$2:$G$109,'Daily data (Sep)'!$D$2:$D$109,$A5,'Daily data (Sep)'!$C$2:$C$109,"No",'Daily data (Sep)'!$K$2:$K$109,"Yes")/COUNTIFS('Daily data (Sep)'!$D$2:$D$109,$A5,'Daily data (Sep)'!$C$2:$C$109,"No",'Daily data (Sep)'!$K$2:$K$109,"Yes")+2*SUMIFS('Daily data (Sep)'!$G$2:$G$109,'Daily data (Sep)'!$D$2:$D$109,$A5,'Daily data (Sep)'!$C$2:$C$109,"Yes",'Daily data (Sep)'!$K$2:$K$109,"Yes")/COUNTIFS('Daily data (Sep)'!$D$2:$D$109,$A5,'Daily data (Sep)'!$C$2:$C$109,"Yes",'Daily data (Sep)'!$K$2:$K$109,"Yes")) -> 0.76163849 | J5: 20 | K5: 7 | L5: =C5+C5/(2*I5/5+2*(1-I5)/2)*(J5*I5/5+K5*(1-I5)/2) -> 331410.78 | M5: =L5/B5-1 -> 0.076009014
A6: Credit Cards | B6: 125000 | C6: 15340 | D6: 4 | E6: 31 | F6: =C6/D6*E6 -> 118885 | G6: =F6/B6-1 -> -0.04892 | H6: =(B6-C6)/(E6-D6) -> 4061.4815 | I6: =5*SUMIFS('Daily data (Sep)'!$G$2:$G$109,'Daily data (Sep)'!$D$2:$D$109,$A6,'Daily data (Sep)'!$C$2:$C$109,"No",'Daily data (Sep)'!$K$2:$K$109,"Yes")/COUNTIFS('Daily data (Sep)'!$D$2:$D$109,$A6,'Daily data (Sep)'!$C$2:$C$109,"No",'Daily data (Sep)'!$K$2:$K$109,"Yes")/(5*SUMIFS('Daily data (Sep)'!$G$2:$G$109,'Daily data (Sep)'!$D$2:$D$109,$A6,'Daily data (Sep)'!$C$2:$C$109,"No",'Daily data (Sep)'!$K$2:$K$109,"Yes")/COUNTIFS('Daily data (Sep)'!$D$2:$D$109,$A6,'Daily data (Sep)'!$C$2:$C$109,"No",'Daily data (Sep)'!$K$2:$K$109,"Yes")+2*SUMIFS('Daily data (Sep)'!$G$2:$G$109,'Daily data (Sep)'!$D$2:$D$109,$A6,'Daily data (Sep)'!$C$2:$C$109,"Yes",'Daily data (Sep)'!$K$2:$K$109,"Yes")/COUNTIFS('Daily data (Sep)'!$D$2:$D$109,$A6,'Daily data (Sep)'!$C$2:$C$109,"Yes",'Daily data (Sep)'!$K$2:$K$109,"Yes")) -> 0.73699443 | J6: 20 | K6: 7 | L6: =C6+C6/(2*I6/5+2*(1-I6)/2)*(J6*I6/5+K6*(1-I6)/2) -> 121726.5 | M6: =L6/B6-1 -> -0.026187973
A7: Pet Insurance | B7: 71300 | C7: 9030 | D7: 4 | E7: 31 | F7: =C7/D7*E7 -> 69982.5 | G7: =F7/B7-1 -> -0.018478261 | H7: =(B7-C7)/(E7-D7) -> 2306.2963 | I7: =5*SUMIFS('Daily data (Sep)'!$G$2:$G$109,'Daily data (Sep)'!$D$2:$D$109,$A7,'Daily data (Sep)'!$C$2:$C$109,"No",'Daily data (Sep)'!$K$2:$K$109,"Yes")/COUNTIFS('Daily data (Sep)'!$D$2:$D$109,$A7,'Daily data (Sep)'!$C$2:$C$109,"No",'Daily data (Sep)'!$K$2:$K$109,"Yes")/(5*SUMIFS('Daily data (Sep)'!$G$2:$G$109,'Daily data (Sep)'!$D$2:$D$109,$A7,'Daily data (Sep)'!$C$2:$C$109,"No",'Daily data (Sep)'!$K$2:$K$109,"Yes")/COUNTIFS('Daily data (Sep)'!$D$2:$D$109,$A7,'Daily data (Sep)'!$C$2:$C$109,"No",'Daily data (Sep)'!$K$2:$K$109,"Yes")+2*SUMIFS('Daily data (Sep)'!$G$2:$G$109,'Daily data (Sep)'!$D$2:$D$109,$A7,'Daily data (Sep)'!$C$2:$C$109,"Yes",'Daily data (Sep)'!$K$2:$K$109,"Yes")/COUNTIFS('Daily data (Sep)'!$D$2:$D$109,$A7,'Daily data (Sep)'!$C$2:$C$109,"Yes",'Daily data (Sep)'!$K$2:$K$109,"Yes")) -> 0.7183316 | J7: 20 | K7: 7 | L7: =C7+C7/(2*I7/5+2*(1-I7)/2)*(J7*I7/5+K7*(1-I7)/2) -> 70274.646 | M7: =L7/B7-1 -> -0.014380844
A8: Business Software (CRM) | B8: 71000 | C8: 7860 | D8: 4 | E8: 31 | F8: =C8/D8*E8 -> 60915 | G8: =F8/B8-1 -> -0.14204225 | H8: =(B8-C8)/(E8-D8) -> 2338.5185 | I8: =5*SUMIFS('Daily data (Sep)'!$G$2:$G$109,'Daily data (Sep)'!$D$2:$D$109,$A8,'Daily data (Sep)'!$C$2:$C$109,"No",'Daily data (Sep)'!$K$2:$K$109,"Yes")/COUNTIFS('Daily data (Sep)'!$D$2:$D$109,$A8,'Daily data (Sep)'!$C$2:$C$109,"No",'Daily data (Sep)'!$K$2:$K$109,"Yes")/(5*SUMIFS('Daily data (Sep)'!$G$2:$G$109,'Daily data (Sep)'!$D$2:$D$109,$A8,'Daily data (Sep)'!$C$2:$C$109,"No",'Daily data (Sep)'!$K$2:$K$109,"Yes")/COUNTIFS('Daily data (Sep)'!$D$2:$D$109,$A8,'Daily data (Sep)'!$C$2:$C$109,"No",'Daily data (Sep)'!$K$2:$K$109,"Yes")+2*SUMIFS('Daily data (Sep)'!$G$2:$G$109,'Daily data (Sep)'!$D$2:$D$109,$A8,'Daily data (Sep)'!$C$2:$C$109,"Yes",'Daily data (Sep)'!$K$2:$K$109,"Yes")/COUNTIFS('Daily data (Sep)'!$D$2:$D$109,$A8,'Daily data (Sep)'!$C$2:$C$109,"Yes",'Daily data (Sep)'!$K$2:$K$109,"Yes")) -> 0.86168438 | J8: 20 | K8: 7 | L8: =C8+C8/(2*I8/5+2*(1-I8)/2)*(J8*I8/5+K8*(1-I8)/2) -> 71829.15 | M8: =L8/B8-1 -> 0.011678166
A10: Weekday share of weekly spend is calculated from each vertical's September baseline days (green: pulled from "Daily data (Sep)"). Monthly budgets and month-to-date spend are synthetic inputs for this exercise.
A11: Why two projections? October started on a Thursday, so two of the first four days were weekend days. A straight-line projection ignores that; the day-weighted one does not.
